Workbook

Sheet Compras
A1: MATERIAIS DO ROBÔ DA LARA · v6.0
A2: Atualizado em 14/09/2026. ⚠️ Correção: os três microfones MEMS I2S e os dois MAX98357A foram comprados para o CAPACETE, não para o robô — a v5.1 contava-os aqui. O robô continua sem ouvidos: uma cápsula MEMS I2S não faz AEC, e isso é processamento, não microfone. Daí o reSpeaker. A coluna tem dois altifalantes de 8 Ω e liga ao reSpeaker. Preços do grupo 3 verificados a 14/09/2026 com loja e referência; o resto continua estimativa antiga e está marcado como tal.
A4: Grupo | B4: Etapa | C4: Peça | D4: Uso nesta arquitetura | E4: Onde vive · dimensão crítica | F4: Qtd | G4: Preço un. | H4: Total | I4: Loja · referência | J4: Estado | K4: Próximo passo
A5: 1 · Em casa | B5: 1 | C5: Raspberry Pi 5 · 4 GB | D5: Corpo, palavra-chave, visão e reconhecimento de pessoas. | E5: Torso, por baixo · 85×56 mm + cooler | F5: 1 | H5: =IF(G5="","",F5*G5) | I5: Em casa | J5: Confirmado | K5: Correr vigiar_energia.py com a fonte de 27 W e exigir EXT5V > 4,95 V sob carga.
A6: 1 · Em casa | B6: 1 | C6: mBot2 completo | D6: Rodas, CyberPi, shield, encoders, giroscópio. Fica inteiro e liga por USB. | E6: É a base do robô · ~17×13 cm | F6: 1 | H6: =IF(G6="","",F6*G6) | I6: Em casa | J6: Confirmado | K6: Etapa 1: spike_mbot2.py com as rodas no ar. Registar que roda é EM1 e EM2.
A7: 1 · Em casa | B7: 1 | C7: Sensor ultrassónico do mBot2 | D7: Obstáculos em frente. Não vê a parede ao lado (reflexão especular). | E7: Frente do mBot2 | F7: 1 | H7: =IF(G7="","",F7*G7) | I7: No mBot2 | J7: Confirmado | K7: Ler distância e fazer com que leitura ausente ou antiga impeça movimento.
A8: 1 · Em casa | B8: 2 | C8: Sensor RGB quádruplo do mBot2 | D8: Quatro canais para linha, cor e hipótese de borda frontal. | E8: Frente, 5–15 mm do chão | F8: 1 | H8: =IF(G8="","",F8*G8) | I8: No mBot2 | J8: Testar | K8: Etapa 2: medir L2/L1/R1/R2 em seis condições. Não é proteção validada contra quedas.
A9: 1 · Em casa | B9: 4 | C9: Câmara para Raspberry Pi | D9: Captura para YuNet e SFace, tudo no Pi. | E9: Cabeça, atrás do faceplate | F9: 1 | H9: =IF(G9="","",F9*G9) | I9: Em casa | J9: Confirmar modelo | K9: Registar modelo e confirmar que tens o cabo CSI 22→15 pinos — sem ele o Pi 5 não vê a câmara.
A10: 1 · Em casa | B10: 1 | C10: Cartão microSD 64 GB | D10: Sistema, código e assinaturas de rosto. | E10: No Pi | F10: 1 | H10: =IF(G10="","",F10*G10) | I10: Em casa | J10: Confirmado | K10: Verificar o cartão: houve bus error no import cv2 depois dos cortes de corrente.
A11: 1 · Em casa | B11: 1 | C11: Dissipador ativo do Pi | D11: Arrefecimento durante visão contínua. | E11: Por cima do Pi · +10 mm de altura | F11: 1 | H11: =IF(G11="","",F11*G11) | I11: Em casa | J11: Confirmado | K11: Medido 45–62 °C — não era térmico o problema da fase 9.
A12: 1 · Em casa | B12: 1 | C12: Fonte de 5 V / 3 A | D12: Só ensaios leves. | E12: Bancada | F12: 1 | H12: =IF(G12="","",F12*G12) | I12: Em casa | J12: Uso limitado | K12: Não ligar Pi, áudio e ecrã juntos a esta fonte.
A13: 1 · Em casa | B13: 3 | C13: ESP32 antigo com Micro-USB | D13: Controlador da cara se o HUB75 ganhar. De cerca de 2017. | E13: Torso, perto do painel | F13: 1 | H13: =IF(G13="","",F13*G13) | I13: Em casa | J13: Por identificar | K13: Fotografar as marcações dos dois lados, compilar o firmware e responder ao ping série SEM painel ligado.
A14: 1 · Em casa | B14: - | C14: Adafruit Feather RP2040 CAN Bus | D14: Reserva. Não integrar sem uma necessidade medida. | E14: Gaveta | F14: 1 | H14: =IF(G14="","",F14*G14) | I14: Em casa | J14: Guardar | K14: Fica para a lição de CAN da v2.
A15: 1 · Em casa | B15: - | C15: Adafruit Feather M4 CAN Express | D15: Reserva. Não integrar sem uma necessidade medida. | E15: Gaveta | F15: 1 | H15: =IF(G15="","",F15*G15) | I15: Em casa | J15: Guardar | K15: Fica para a lição de CAN da v2.
A16: 1 · Em casa | B16: 6 | C16: mac mini | D16: Transcrição, LLM e síntese de voz. Não recebe imagens nem rostos. | E16: Fora do robô, na LAN | F16: 1 | H16: =IF(G16="","",F16*G16) | I16: Em casa | J16: Confirmado | K16: Ollama a ouvir em 0.0.0.0 e testado de outro computador.
... A26: 2 · Recebido para o robô | B26: 5 | C26: Interruptor rocker preto 20 mm | D26: Candidato a corte físico de um circuito. | E26: Furo de 20 mm no corpo | F26: 1 | H26: =IF(G26="","",F26*G26) | I26: Recebido | J26: Contactos por medir | K26: Confirmar corrente e tensão nominais antes de o pôr no caminho de alimentação.
A27: 3 · COMPRAR AGORA | B27: 6 | C27: reSpeaker Mic Array v2.0 · 4 microfones (XMOS XVF-3000) | D27: AEC em hardware, beamforming e deteção de direção, e placa de som USB. DECIDIDO 15/09 em vez do Lite, porque a Botland é mesmo só B2B. ⚠ A saída é ANALÓGICA (jack 3,5 mm, codec WM8960) — não liga ao MAX98357A, que só aceita I2S digital. | E27: Torso · placa da Seeed · confirmar espaço no cartão | F27: 1 | G27: 55.3 | H27: =IF(G27="","",F27*G27) -> 55.3 | I27: Mauser 096-8389 · 4 em stock | J27: Decidido · em falta | K27: NÃO dessoldar o jack: cortar um cabo jack-macho de €2 e soldar aí, que é reversível e não arrisca as pistas de uma placa de €55. Primeiro experimentar o jack direto na coluna — se der volume que chegue, não é preciso amplificador nenhum.
A28: 3 · COMPRAR AGORA | B28: 6 | C28: Amplificador analógico PAM8403 (Whadda WPI411) | D28: Entre o jack do reSpeaker e a coluna passiva. Estéreo 2×3 W, 4–8 Ω: um só módulo toca os DOIS altifalantes de 8 Ω. | E28: Torso, junto da coluna · alimenta-se a 5 V | F28: 1 | G28: 7.65 | H28: =IF(G28="","",F28*G28) -> 7.65 | I28: Mauser 047-3485 · 14 em stock | J28: Decidido · em falta | K28: Só é preciso se o jack sozinho não der volume — mas a €7,65 e na MESMA encomenda, é mais barato tê-lo do que fazer um segundo envio por causa dele.
A29: 4 · Bloqueado numa medição | B29: - | C29: reSpeaker XVF3800 (4 mics) — upgrade | D29: Só acrescenta beamforming e deteção de direção ao que o Lite já faz. O AEC é igual nos dois. | E29: Torso · 108×108×18 mm | F29: 1 | H29: =IF(G29="","",F29*G29) | I29: Sem loja que envie p/ PT | J29: Só se fizer falta | K29: Reabrir apenas se a deteção de direção (virar-se para quem fala) se mostrar necessária. A câmara já diz onde está a pessoa.
A30: 3 · COMPRAR AGORA | B30: 7 | C30: Painel HUB75 RGB 64×32 · pitch 2,5 mm | D30: A cara. O firmware, o protocolo série e as 19 expressões já existem. | E30: ⚠ Cabeça · 160×80×14 mm — o pitch de 4 mm daria 256×128 mm e NÃO cabe | F30: 1 | G30: 47.33 | H30: =IF(G30="","",F30*G30) -> 47.33 | I30: DigiKey PT 1528-5036-ND · 145 stock | J30: Decidido · em falta | K30: Mudou da BerryBase (€44,90, 1 em stock) para a DigiKey: €2,43 mais caro e 145 em stock, mas entra na MESMA encomenda do reSpeaker e é ela que empurra o total acima dos €75. A ficha confirma 160,00 × 80,00 × 14,70 mm.
A31: 3 · COMPRAR AGORA | B31: 7 | C31: Cablagem HUB75 ↔ ESP32 + cabo de alimentação do painel | D31: Liga o painel ao ESP32, e alimenta o painel a 5 V — o cabo de força não vem com ele. | E31: Torso | F31: 1 | G31: 14.63 | H31: =IF(G31="","",F31*G31) -> 14.63 | I31: DigiKey 1528-4767 (€2,63) + estimativa | J31: Estimativa | K31: O cabo de alimentação do painel é a ref. Adafruit 4767, €2,14 s/IVA. O resto (fios, protoboard) continua estimativa.
A32: 3 · COMPRAR AGORA | B32: 7 | C32: Acrílico preto de difusão 2–3 mm (~170×90 mm) | D32: Sem ele vêem-se 2048 LEDs numa placa; com ele, dois olhos a brilhar num visor escuro. É preciso para QUALQUER ecrã. | E32: Cabeça, à frente do ecrã | F32: 1 | G32: 14 | H32: =IF(G32="","",F32*G32) -> 14 | I32: Estimativa · revalidar | J32: Estimativa | K32: Comprar JÁ: é a peça que permite fazer o teste do telemóvel e decidir o ecrã sem gastar €109.
A33: 3 · COMPRAR AGORA | B33: - | C33: 2× sensor ToF VL53L1X (4 m, I2C) | D33: Ver as paredes DE LADO. O ultrassónico não vê a parede ao lado da qual anda — é a causa dos embates no corredor. | E33: Cantos dianteiros · módulo pequeno | F33: 2 | G33: 9.99 | H33: =IF(G33="","",F33*G33) -> 19.98 | I33: Mauser 095-9477 · 31 em stock | J33: Decidido · em falta | K33: ✅ 15/09: MAUSER tem o VL53L1X a €9,99 c/IVA (31 em stock, Freixeira) — bate a Botnroll (€16,95), a DigiKey (€23,59) e a Amazon (€16,89, marca Wakects, 0 críticas, 2 em stock). 5+ unidades a €8,00 cada — vale pensar se queres já cobrir a proteção traseira de bordas. ⚠ Dois no mesmo I2C partilham endereço: sequenciar pelo XSHUT. ⚠ REJEITADO: pack GERUI de 6 na Amazon (B0D3PRSV3B) é VL53L0X, não L1X, com críticas de 1 em 4 a funcionar, e não envia para PT.
A34: 4 · Bloqueado numa medição | B34: 7 | C34: Candidato OLED · Waveshare 5,5" AMOLED HDMI 1080×1920 | D34: O outro lado da comparação da cara. Ganha em preto absoluto, perde em arranque (Chromium em quiosque) e em preço. | E34: Cabeça · 5,5" · vidro temperado | F34: 1 | G34: 109 | H34: =IF(G34="","",F34*G34) -> 109 | I34: Welectron 16103 · ~3 meses | J34: NÃO comprar ainda | K34: FAZER PRIMEIRO, e custa €0: põe o bot-face no telemóvel (ecrã OLED) atrás do acrílico, a 2 m, com luz de quarto e luz do dia. Só se o OLED ganhar claramente é que vale €109 e três meses.
A35: 4 · Bloqueado numa medição | B35: 5 | C35: Corte físico de movimento · botão DPST + fusível | D35: Parar o robô sem rede, sem USB e sem processo Python. | E35: Traseira do corpo, ao alcance de um adulto | F35: 1 | G35: 24 | H35: =IF(G35="","",F35*G35) -> 24 | I35: Estimativa · revalidar | J35: Por desenhar | K35: Bloqueado em: medir os contactos do botão de 28 mm e do rocker de 20 mm que já tens. Só comprar se nenhum servir.
A36: 4 · Bloqueado numa medição | B36: 3 | C36: Proteção traseira contra bordas | D36: O sensor RGB do mBot2 só cobre a frente. Marcha-atrás e rotação perto de quedas continuam proibidas. | E36: Traseira, virado ao chão | F36: 1 | H36: =IF(G36="","",F36*G36) | I36: Por escolher | J36: Bloqueado | K36: Bloqueado na etapa 2: medir os quatro canais RGB em seis condições antes de escolher.
A37: 4 · Bloqueado numa medição | B37: - | C37: Bateria + carregador + reguladores | D37: Autonomia fora da bancada. | E37: Base do corpo, o mais baixo possível (é o contrapeso) | F37: 1 | H37: =IF(G37="","",F37*G37) | I37: Por dimensionar | J37: Bloqueado | K37: Bloqueado em medir o consumo. ⚠ Com o mBot2 inteiro o barramento de 7,4 V dos motores provavelmente desaparece (−€35) e há uma pergunta nova: uma bateria só, ou a do mBot2 mais uma para o Pi?
A38: 5 · Depois do conjunto básico | B38: 11 | C38: PCA9685 para os braços | D38: Controla servos. Não controla as rodas. | E38: Torso | F38: 1 | G38: 8 | H38: =IF(G38="","",F38*G38) -> 8 | I38: Estimativa antiga | J38: Adiar | K38: Pino OE com pull-up: sem isso um kill -9 deixa os servos presos.
A39: 5 · Depois do conjunto básico | B39: 11 | C39: Servos DS3218 para os ombros | D39: Movimento dos ombros, ~16 kg·cm a 5,7 V. | E39: Ombros | F39: 2 | G39: 18 | H39: =IF(G39="","",F39*G39) -> 36 | I39: Estimativa antiga | J39: Adiar | K39: Desenhar o braço em cartão primeiro. Barramento de 5,7 V / 6 A, nunca dos 5 V do Pi.
A40: 5 · Depois do conjunto básico | B40: 11 | C40: Servos MG90S para cotovelos e garra | D40: Movimento leve dos braços. | E40: Cotovelos e garra | F40: 3 | G40: 6 | H40: =IF(G40="","",F40*G40) -> 18 | I40: Estimativa antiga | J40: Adiar | K40: Validar quantidade e limites antes de comprar.
A41: 5 · Depois do conjunto básico | B41: 11 | C41: Suportes e ferragem dos braços | D41: Fixação dos servos e das juntas. | E41: Braços | F41: 1 | G41: 15 | H41: =IF(G41="","",F41*G41) -> 15 | I41: Estimativa antiga | J41: Adiar | K41: Depois do cartão.
A42: 5 · Depois do conjunto básico | B42: - | C42: Cartão e materiais de protótipo do corpo | D42: Descobrir proporções e acesso aos cabos. A coisa mais valiosa da lista toda. | E42: É o corpo inteiro, em tamanho real | F42: 1 | G42: 35 | H42: =IF(G42="","",F42*G42) -> 35 | I42: Estimativa antiga | J42: Fazer já, sem comprar | K42: Caixas de cereais e fita-cola chegam para começar hoje. Reservar o volume do reSpeaker (108×108) e do painel (160×80).
A43: 5 · Depois do conjunto básico | B43: - | C43: Materiais do corpo final | D43: Estrutura, acabamento e faceplate. | E43: Corpo | F43: 1 | H43: =IF(G43="","",F43*G43) | I43: Por decidir | J43: Adiar | K43: Escolher depois do ecrã e do protótipo em cartão.
A44: 5 · Depois do conjunto básico | B44: - | C44: Sensores de toque TTP223 | D44: Interações de toque na cabeça e no corpo. | E44: Cabeça, costas e frente | F44: 3 | G44: 2 | H44: =IF(G44="","",F44*G44) -> 6 | I44: Estimativa antiga | J44: Adiar | K44: Os €6 com melhor relação efeito/preço do projeto — mas só depois da demonstração básica.
A45: 5 · Depois do conjunto básico | B45: - | C45: LEDs decorativos e resistências | D45: Luzes do peito e da base. | E45: Peito e base | F45: 1 | G45: 6 | H45: =IF(G45="","",F45*G45) -> 6 | I45: Estimativa antiga | J45: Adiar | K45: Nos PCA9685 dos MOTORES (1 kHz), nunca no dos servos.
A46: 5 · Depois do conjunto básico | B46: - | C46: Sobressalentes | D46: Um MG90S extra, fusíveis, cabos. | E46: Gaveta | F46: 1 | G46: 25 | H46: =IF(G46="","",F46*G46) -> 25 | I46: Estimativa antiga | J46: Adiar | K46: Num projeto de 4 meses, esperar uma semana por uma peça de €5 mata o ritmo.
A47: 6 · Não comprar | B47: - | C47: TB6612FNG para as rodas | D47: Duplicaria a ponte de motores do mBot2 Shield. | E47: — | F47: 1 | H47: =IF(G47="","",F47*G47) | I47: Não comprar | J47: Retirado | K47: O mBot2 fica inteiro.
A48: 6 · Não comprar | B48: - | C48: PCA9685 para os motores | D48: As rodas são comandadas pelo shield por USB. | E48: — | F48: 1 | H48: =IF(G48="","",F48*G48) | I48: Não comprar | J48: Retirado | K48: Reservar um PCA9685 futuro apenas para os braços.
A49: 6 · Não comprar | B49: - | C49: HC-SR04P e TCRT5000 | D49: Duplicam o ultrassónico e o RGB do mBot2. | E49: — | F49: 2 | H49: =IF(G49="","",F49*G49) | I49: Não comprar | J49: Retirado | K49: Reabrir só se as medições mostrarem uma lacuna.
A50: 6 · Não comprar | B50: - | C50: Segundo MAX98357A | D50: A coluna liga ao reSpeaker, não ao Pi — nem o primeiro MAX98357A fica no caminho. | E50: — | F50: 1 | H50: =IF(G50="","",F50*G50) | I50: Não comprar | J50: Retirado | K50: Um amplificador a tocar AO LADO do reSpeaker deixa-o sem referência e mata o AEC.
...

Sheet Resumo
A1: ESTADO DOS MATERIAIS · v6.1
A2: ⚠️ Correção de 14/09/2026: os três microfones MEMS I2S e os dois MAX98357A foram comprados para o CAPACETE — a v5.1 contava-os como material do robô. O robô nunca teve ouvidos. E uma cápsula MEMS I2S não resolve isso: o que falta é AEC, que é processamento e não microfone. Daí o reSpeaker. A coluna tem dois altifalantes de 8 Ω e liga ao reSpeaker. A cara continua em comparação, agora com preços reais dos dois lados.
A4: Grupo | B4: Quando agir | C4: Nº de linhas | D4: Subtotal
A5: 1 · Em casa | B5: Usar e medir agora | C5: =COUNTIF(Compras!$A$5:$A$52,$A5) -> 13 | D5: =SUMIF(Compras!$A$5:$A$52,$A5,Compras!$H$5:$H$52) -> 0
A6: 2 · Recebido para o robô | B6: Testado — falta escrever o inventário | C6: =COUNTIF(Compras!$A$5:$A$52,$A6) -> 7 | D6: =SUMIF(Compras!$A$5:$A$52,$A6,Compras!$H$5:$H$52) -> 0
A7: 3 · COMPRAR AGORA | B7: Decidido e em falta. É isto que desbloqueia o próximo mês | C7: =COUNTIF(Compras!$A$5:$A$52,$A7) -> 6 | D7: =SUMIF(Compras!$A$5:$A$52,$A7,Compras!$H$5:$H$52) -> 158.89
A8: 4 · Bloqueado numa medição | B8: Não falta dinheiro, falta uma medição | C8: =COUNTIF(Compras!$A$5:$A$52,$A8) -> 5 | D8: =SUMIF(Compras!$A$5:$A$52,$A8,Compras!$H$5:$H$52) -> 133
A9: 5 · Depois do conjunto básico | B9: Adiar até à etapa indicada | C9: =COUNTIF(Compras!$A$5:$A$52,$A9) -> 9 | D9: =SUMIF(Compras!$A$5:$A$52,$A9,Compras!$H$5:$H$52) -> 149
A10: 6 · Não comprar | B10: Retirar dos carrinhos | C10: =COUNTIF(Compras!$A$5:$A$52,$A10) -> 6 | D10: =SUMIF(Compras!$A$5:$A$52,$A10,Compras!$H$5:$H$52) -> 0
A11: 7 · Comprado para os dois projetos | B11: Comprados a dobrar de propósito, para servirem os dois. No robô não dá — o que lá falta é AEC, não microfones. Ficam no capacete do stormtrooper e no do Vader. | C11: =COUNTIF(Compras!$A$5:$A$52,$A11) -> 2 | D11: =SUMIF(Compras!$A$5:$A$52,$A11,Compras!$H$5:$H$52) -> 0
A13: A COMPRAR AGORA (grupo 3) | D13: =SUMIF(Compras!$A$5:$A$52,"3 · COMPRAR AGORA",Compras!$H$5:$H$52) -> 158.89
A14: Subtotal conhecido (inclui os €109 do OLED e os €24 do DPST, que podem não ser precisos) | D14: =SUM(Compras!$H$5:$H$52) -> 440.89
A15: Se o teste do telemóvel dispensar o OLED, poupa-se | D15: =-109 -> -109
A16: Orçamento máximo | D16: =1000 -> 1000
A17: Folga face ao orçamento | D17: =D16-D14 -> 559.11
A19: ORDEM DE TRABALHO — pela ordem, não à escolha
A20: 1. Escrever o inventário. Testaste as peças mas não ficou registado — docs/componentes.md ainda diz «por identificar», e foi assim que as peças do capacete acabaram a contar como material do robô.
A21: 2. Confirmar na etiqueta que chip são os três microfones (o pack de 3 mais comum é INMP441) e anotá-lo na bancada do capacete.
A22: 3. Medir os contactos do botão de 28 mm e do rocker de 20 mm. É a única coisa que decide se há um DPST a comprar.
A23: 4. Correr vigiar_energia.py --forcar 90 com a fonte de 27 W. Exigir EXT5V > 4,95 V. Desbloqueia a visão E os periféricos USB — o reSpeaker incluído.
A24: 5. Encomendar o grupo 3. O reSpeaker tem 9 unidades em stock na Gotronic e é o que desbloqueia mais etapas.
A25: 6. Ler os encoders do mBot2 na navegação. É software, o hardware já lá está, e corta o erro de 23 cm na origem.
A26: 7. Teste do telemóvel atrás do acrílico, a 2 m, com luz de quarto e luz do dia. Decide os €109 do OLED sem os gastar.
A27: 8. Corpo em cartão, em tamanho real. Reservar 108×108×18 mm para o reSpeaker e 160×80×14 mm para o painel.
A28: 9. Medir o consumo do conjunto antes de escolher bateria e reguladores.

Sheet Alternativas
A1: DECISÕES DE HARDWARE · v6.0
A2: Atualizado a 14/09/2026 com o resultado do teste dos microfones.
A4: Item | B4: Preço | C4: Categoria | D4: Veredicto | E4: Porquê
A5: mBot2 completo por USB | C5: Movimento | D5: ESCOLHIDO | E5: O POC passou. Conserva motores, encoders, giroscópio, ultrassons e RGB. Medido: drive_speed 61 ms, encoder subscrito ~0 ms.
A6: Ultrassónico do mBot2 | C6: Obstáculos | D6: USAR — com um limite | E6: Serve para a frente. NÃO vê a parede ao lado da qual anda: reflexão especular. É por isso que os VL53L1X entram.
A7: Quad RGB do mBot2 | C7: Linha, cor e borda | D7: TESTAR | E7: Quatro canais, reflexão 0–100. A hipótese da borda é para medir, não para assumir. O fabricante não o vende como proteção contra quedas.
A8: reSpeaker XVF3800 | B8: 59.9 | C8: Ouvir e falar | D8: ESCOLHIDO — comprar | E8: Os três microfones recebidos são MEMS I2S: sem AEC, e o Pi 5 passou o I2S para o RP1. O AEC é um problema MONO e faz-se em hardware ou não se faz. É também a placa de som.
A9: 3× microfone MEMS I2S (do capacete) | C9: Ouvir | D9: NÃO SERVE AO ROBÔ | E9: Foram comprados para o capacete e um deles já lá está a funcionar. Uma cápsula MEMS I2S entrega amostras em bruto: dois microfones crus sem AEC são o pior dos dois mundos. Sobram dois para a bancada e para a Lara.
A10: MAX98357A no Pi | C10: Falar | D10: RETIRADO | E10: Os dois que há são do capacete. No robô tocaria AO LADO do reSpeaker e deixava-o sem sinal de referência — os €60 do AEC deixavam de servir para nada. A coluna liga ao reSpeaker.
A11: Segundo MAX98357A | C11: Falar | D11: NÃO COMPRAR | E11: Nem o primeiro fica no robô. Os dois altifalantes de 8 Ω ligam-se pela saída do reSpeaker.
A12: reSpeaker Lite (plano B) | B12: 25 | C12: Ouvir | D12: FORA — loja só B2B | E12: Melhor arquitetura (saída amplificada, dispensava o PAM8403), mas a Botland só vende a empresas e mais nenhuma loja com envio para PT o tem a preço decente.
A13: HUB75 P2.5 64×32 + ESP32 | B13: 56.9 | C13: Cara | D13: CANDIDATO A — favorito | E13: Firmware, protocolo série e 19 expressões já existem. 160×80 mm cabe atrás de um faceplate de 170×90. Animação fora do Pi. Painel €44,90 + cablagem €12.
A14: HUB75 pitch 4 mm | B14: 28.6 | C14: Cara | D14: REJEITADO | E14: Mais barato, mas mede 256×128 mm. Não cabe na cabeça. O pitch é a dimensão que decide, não o preço.
A15: OLED 5,5" AMOLED HDMI | B15: 109 | C15: Cara | D15: CANDIDATO B — caro e lento | E15: Preto absoluto atrás do acrílico é o argumento forte. Contra: €109, ~3 meses de entrega, Chromium em quiosque, arranque mais lento e risco de burn-in.
A16: Teste do telemóvel atrás do acrílico | B16: 0 | C16: Cara | D16: FAZER PRIMEIRO | E16: O telemóvel É um OLED. Mostra o bot-face atrás do acrílico, a 2 m, com luz de quarto e luz do dia. Responde à pergunta toda por €0.
A17: GC9A01 / LCD pequeno | C17: Cara | D17: REJEITADO | E17: 280 nits atrás de acrílico a 18% dão ~50 nits: a luz emitida atravessa 1×, os reflexos 2×. Ilegível.
A18: HUB75 direto no Pi 5 | C18: Cara | D18: REJEITADO | E18: PioMatter precisa de 13 pinos e cinco colidem: 17/22/27 precipício, 23 ultrassons, 21 I2S.
A19: 2× VL53L1X nos cantos | B19: 33.9 | C19: Navegação | D19: COMPRAR | E19: Medido: bate com a posição verdadeira a 23 cm da crença, num corredor que só dá ±38 cm de margem. E o ultrassom não vê a parede do lado.
A20: Ler os encoders na navegação | B20: 0 | C20: Navegação | D20: FAZER PRIMEIRO | E20: Corta o erro na origem e o hardware já lá está. Afinar o piloto antes disto é afinar contra uma margem que não existe.
A21: Barramento de 7,4 V para motores | C21: Energia | D21: PROVAVELMENTE SAI | E21: Era para motores tirados do mBot2. O mBot2 fica inteiro e tem alimentação própria — poupa ~€35, mas abre a pergunta de quantas baterias há.
A22: Bateria LiFePO4 4S | C22: Energia | D22: POR DIMENSIONAR | E22: Química que não liberta oxigénio — a troca certa com uma criança por perto. Mas não se escolhe antes de medir o consumo.
A23: Power bank USB-C de duas saídas | C23: Energia | D23: NÃO | E23: Não negoceia 5 V/5 A, e sem esse perfil o Pi limita TODAS as portas USB a 600 mA — o que mata o reSpeaker.
A24: YuNet e SFace no Pi | C24: Visão | D24: ESCOLHIDO | E24: Imagens e assinaturas nunca saem do Pi.
A25: STT, LLM e TTS no mac mini | C25: Conversa | D25: ESCOLHIDO | E25: Só a palavra-chave e a visão ficam no Pi.
A26: Acelerador de IA | C26: Processamento | D26: NÃO | E26: YuNet e SFace cabem no CPU do Pi. O resto já corre no mini.
A27: reSpeaker Mic Array v2.0 (Mauser) | B27: 55.3 | C27: Ouvir e falar | D27: ESCOLHIDO 15/09 | E27: XMOS XVF-3000: AEC + beamforming + deteção de direção (DoA) e 4 microfones. LOJA PORTUGUESA, 4 em stock. ⚠ A saída é só jack de 3,5 mm — a coluna passiva de 8 Ω precisa de um amplificador analógico (PAM8403, ~€3); o MAX98357A é I2S e NÃO serve aqui. Ref. 096-8389.
A28: reSpeaker Lite (2 mics) | B28: 26.22 | C28: Ouvir e falar | D28: FORA — loja só B2B | E28: Melhor arquitetura (saída amplificada, dispensava o PAM8403), mas a Botland só vende a empresas e mais nenhuma loja com envio para PT o tem a preço decente.
A29: VL53L1X na Mauser | B29: 9.99 | C29: Navegação | D29: COMPRAR AQUI | E29: €9,99 c/IVA, 31 em stock, loja portuguesa. Metade do preço da Botnroll e 2,4× mais barato que a DigiKey. 5+ a €8,00.

Sheet Lojas
A1: ONDE COMPRAR · v6.0
A2: Preços confirmados a 14/09/2026 onde diz «verificado». Revalidar sempre preço, stock e portes antes de carregar em comprar.
A4: Loja | B4: País | C4: Site | D4: O que comprar lá, e o aviso
A5: Gotronic | B5: França | C5: gotronic.fr | D5: ⚠️ NÃO ENVIA PARA PORTUGAL (confirmado pelo Bruno, 14/09/2026). Tinha o reSpeaker a €59,90, mas não serve. Não voltar a propor esta loja.
A6: Antratek | B6: Holanda | C6: antratek.com | D6: ✅ MELHOR OPÇÃO EM STOCK HOJE para o reSpeaker: €69,00 COM caixa, Holanda. Portes grátis só para NL/DE/BE, por isso PT paga — o valor só aparece no checkout.
A7: BerryBase | B7: Alemanha | C7: berrybase.de | D7: Tinha o painel HUB75 P2.5 (ADA5036) a €44,90, mas só 1 em stock. Saiu da lista: a DigiKey tem o mesmo painel com 145 em stock e conta para os portes grátis. Boa loja para breakouts baratos.
A8: Botnroll | B8: Portugal | C8: botnroll.com | D8: ✅ VERIFICADO: VL53L1X (SEN03042) €16,95. ⚠️ O painel HUB75 que têm é pitch 4 mm (256×128 mm) — grande demais para a cabeça. 💡 PEDIR-LHES O reSpeaker: é loja portuguesa, sem alfândega, e já leva os VL53L1X. Custa um email e resolve o problema todo. A pesquisa interna é péssima: procurar com site:botnroll.com.
A9: Mauser | B9: Portugal | C9: mauser.pt | D9: ✅✅ LOJA PORTUGUESA, e melhor do que eu julgava. VERIFICADO 15/09: VL53L1X (095-9477) €9,99 c/IVA, 31 em stock · reSpeaker Mic Array v2.0 (096-8389) €55,30, XVF-3000 com AEC+DoA, 4 em stock · Camera Module 3 €29,99 e cabo SC1892 €1,17. SETE lojas com levantamento GRÁTIS, Porto incluído — ⚠ mas o stock é por loja, e estes dois estão em Freixeira. Portes €3,49 abaixo de €50, grátis acima. ⚠ Não comprar aqui o Pi 5.
A10: PTRobotics | B10: Portugal | C10: ptrobotics.com | D10: Bom catálogo e envio rápido. ⚠ O site bloqueia leitura automática — tens de confirmar preços à mão. Só tem HUB75 de pitch 3 e 4 mm.
A11: Welectron | B11: Alemanha | C11: welectron.com | D11: O OLED candidato: Waveshare 16103, 5,5" AMOLED HDMI, €109,00. ⚠ ENTREGA ~3 MESES. É a razão para fazer o teste do telemóvel primeiro.
A12: The Pi Hut / Pimoroni | B12: Reino Unido | C12: thepihut.com | D12: Tem o reSpeaker XVF3800 a £52,80 com IVA britânico, em stock. ⚠️ Pós-Brexit: tirar o IVA do Reino Unido, somar portes, IVA português a 23% e uma possível taxa de desalfandegamento dos CTT ANTES de comparar com a Antratek. Também é referência para Adafruit e Pimoroni.
A13: Botland | B13: Polónia | C13: botland.store | D13: ⚠️ SÓ VENDE A CLIENTES B2B REGISTADOS (confirmado pelo Bruno, 14/09/2026). Tinha o reSpeaker a €57,90, mas é preciso conta de empresa. Não voltar a propor.
A15: ANTES DE ENCOMENDAR
A16: ☐ Escrever o inventário do que já chegou — docs/componentes.md ainda diz «por identificar» sobre peças que já testaste
A17: ☐ Medir os contactos do botão de 28 mm e do rocker de 20 mm antes de comprar um DPST
A18: ☐ Confirmar que ficha traz a coluna (JST-PH 2.0 ou jack 3,5 mm) — as duas servem no reSpeaker, sem comprar nada
A19: ☐ Fazer o teste do telemóvel atrás do acrílico antes de gastar €109 e três meses no OLED
A20: ☐ Medir a profundidade disponível na cabeça e no torso antes de fechar o painel e o reSpeaker
A21: ☐ Não comprar bateria nem reguladores antes de medir o consumo do conjunto
A22: ☐ Revalidar preço, stock, portes e compatibilidade de cada referência no dia da encomenda
A24: Amazon.es | B24: Espanha | C24: amazon.es | D24: ⚠️ Para o reSpeaker NÃO SERVE: ASIN B0FKGFXQQ5 está a €181,66 e a página diz «só pode ser enviado para França e Mónaco». Continua a ser boa loja para o resto — foi de lá que vieram os microfones e os MAX98357A.
A25: Kiwi Electronics | B25: Holanda | C25: kiwi-electronics.com | D25: O reSpeaker mais barato da UE: ref. 20794, €48,99 sem IVA — mas ESGOTADO e sem data de reposição (14/09/2026). Vale um alerta de stock; não vale esperar por ele.
A26: DigiKey Portugal | B26: Portugal | C26: digikey.pt | D26: ✅✅ A LOJA PRINCIPAL. Preços em euros, IVA português à vista, vende a particulares, entrega em 48 h. ⚠️⚠️ PORTES: €25 abaixo de €75, GRÁTIS a partir de €75. NUNCA encomendar uma peça sozinha aqui — juntar sempre até passar os €75. Tem: reSpeaker Lite 1597-107990273-ND · painel HUB75 P2.5 1528-5036-ND · cabo de força do painel 1528-4767 · VL53L1X-SATEL. NÃO tem o XVF3800.

Sheet Impressora 3D
A1: IMPRESSORA 3D — INVESTIMENTO FUTURO
A2: NÃO entra no total do robô. Não é preciso para começar: o corpo faz-se em cartão até à fase 13.
A4: Item | B4: Preço | C4: Fechada? | D4: Volume | E4: Veredicto | F4: Porquê
A5: Bambu Lab P1S | B5: 379 | C5: Sim | D5: 256 mm | E5: RECOMENDADA | F5: Fechada (barreira física contra um bico a 250C, com uma criança por perto), filtro de carvão ativado, e 256mm chega para a cúpula da cabeça em 2 metades. Ecossistema mais fácil do mercado para quem começa.
A6: Filamento inicial (PLA branco + azul + PETG) | B6: 45 | C6: — | D6: — | E6: COMPRAR COM | F6: As cores do Astro. O PETG é para as peças que tocam no Pi e nos reguladores — o PLA amolece aos 60C.
A7: Bambu Lab A1 | B7: 259 | C7: NÃO | D7: 256 mm | E7: ALTERNATIVA | F7: Excelente máquina e 120 euros mais barata, mas ABERTA. Com uma criança de 11 anos, esses 120 euros compram uma barreira à volta do bico quente e da mesa que se move.
A8: Bambu Lab A1 mini | B8: 189 | C8: NÃO | D8: 180 mm | E8: EVITAR | F8: ⚠️ 180mm obriga a partir a cúpula da cabeça em 4-6 gomos, com muitas juntas a lixar e colar. Frustração garantida para uma criança.
A9: Elegoo Centauri Carbon 2 Combo | B9: 379 | C9: Sim | D9: 256 mm | E9: ALTERNATIVA FORTE | F9: Fechada E já com multicor, pelo mesmo preço da P1S. A melhor relação preço/valor de 2026, se não fizerem questão do ecossistema Bambu.
A10: Bambu Lab P2S | B10: 519 | C10: Sim | D10: 256 mm | E10: NÃO COMPENSA | F10: A P1S melhorada (out/2025): extrusor DynaSense, deteção de erros por IA. Melhor, mas não 140 euros melhor para este uso.
A11: Prusa MK4S | B11: 719 | C11: Não | D11: 250x210x220 | E11: FORA DO ÂMBITO | F11: Fabricante europeu, open-source, peças e apoio na UE. Ótima máquina, mas o dobro do que este projeto precisa.
A12: AMS lite — impressão multicor | B12: 110 | C12: — | D12: — | E12: NÃO | F12: ⚠️ Parece óbvio para um robô branco e azul, mas não é: desperdiça ~8g de filamento POR TROCA DE COR (81% do filamento numa peça pequena com 8 trocas). As nossas peças são grandes e de UMA cor — troca-se o rolo à mão entre peças, 2 minutos. Só compensaria para várias cores DENTRO da mesma peça.
A13: Purificador de ar HEPA + carvão | B13: 115 | C13: — | D13: — | E13: SE FOR EM CASA | F13: ⚠️ Só se a impressora ficar numa divisão habitada. O filtro de carvão da P1S trata dos COVs mas NÃO É HEPA — não apanha as partículas ultrafinas. Melhor ainda: pôr a impressora na garagem ou num escritório com janela.
A15: PARA ARRANCAR (P1S + filamento) | B15: =B5+B6 -> 424
A17: SEGURANÇA — as cinco regras
A18: Um relatório da UL Chemical Insights, feito em salas de aula, mediu mais de 200 COVs distintos em impressoras FDM, formaldeído acima do dobro do limite recomendado da Califórnia, e 3,4x10^8 partículas ultrafinas por hora mesmo com PLA. O relatório avisa explicitamente para crianças. Ou seja: o PLA é o mais seguro, mas não é seguro sem cuidados.
A19: 1. Impressora FECHADA — barreira física contra queimaduras, contém a maior parte das partículas, e reduz muito o ruído.
A20: 2. NÃO no quarto dela. Garagem, arrumos, ou escritório com janela.
A21: 3. Só PLA e PETG. Nada de ABS ou ASA em casa sem extração para o exterior.
A22: 4. A criança carrega o ficheiro e vê pela câmara; só abre a tampa depois de arrefecer.
A23: 5. O filtro de carvão trata dos COVs mas NÃO É HEPA — não apanha partículas ultrafinas. Daí a regra 2.
A25: CUSTO CONTINUADO
A26: O robô inteiro consome 1,5-2,5 kg de filamento = 25-40 euros.
A27: Eletricidade: cerca de 2 cêntimos por hora. Desprezável — o filamento custa 5 a 50x mais.
A28: Desgaste (bicos 10-15 euros, placa 25-40, correias): orçamentar 40-60 euros por ano.
A29: ⚠️ Uma metade de cúpula demora 8 a 20 HORAS a imprimir. Uma cabeça completa é um fim de semana. Dizer isto à Lara no primeiro dia — a expectativa errada aqui estraga a experiência toda.
A30: ANTES DE COMPRAR: o FabLab Porto (Rua António Carneiro 302-R, seg-sex 14h-20h) e o FabLab Lisboa deixam ver máquinas a trabalhar. Meia hora bem passada antes de gastar 400 euros.

Sheet A bancada
A1: A BANCADA · FERRAMENTAS
A2: Ferramentas duram uma vida e ficam fora do subtotal do robô.
A4: Item | B4: Preço | C4: Essencial? | D4: Porquê / o que escolher
A5: Estação de soldar com base pesada (936 / Yihua) | B5: 30 | C5: SIM | D5: ⚠️ COM UMA CRIANÇA POR PERTO, O SUPORTE PESADO IMPORTA MAIS QUE O FERRO. Uma estação de 30 euros com base estável é mais segura que um ferro portátil pousado na mesa. Ponto de retorno decrescente: ~40 euros. Um Hakko de 120 ou um JBC de 400 não ensinam melhor.
A6: Solda SEM CHUMBO 0,7 mm, 100 g | B6: 14 | C6: SIM | D6: ⚠️ RECOMENDO SEM CHUMBO, e não a 60/40 clássica. Funde a 217C em vez de 183C e molha um pouco pior, mas apaga uma preocupação inteira numa casa com crianças. O manual de segurança da FIRST Robotics exige mesmo 'lead-free solder only'. Diâmetro 0,7 mm: 1 mm é grosso demais para pinos.
A7: Fluxo em caneta, no-clean | B7: 8 | C7: SIM | D7: Com solda sem chumbo o fluxo extra deixa de ser luxo. Uma caneta dura anos.
A8: Lã de latão para limpar a ponta | B8: 6 | C8: SIM | D8: Melhor que a esponja molhada: não arrefece a ponta de repente, o que a faz durar muito mais.
A9: Ponta chisel 2,4 mm de reserva | B9: 5 | C9: SIM | D9: ⚠️ A ponta CHISEL é a certa para principiante — transfere muito mais calor que a de agulha, que é a pior escolha e a que toda a gente experimenta primeiro.
A10: Malha dessoldadora + bomba | B10: 10 | C10: SIM | D10: Para desfazer erros. Vão precisar nas primeiras vinte juntas.
A11: Terceira mão (helping hands) | B11: 8 | C11: SIM | D11: Duas mãos seguram o ferro e a solda; não sobra nenhuma para a placa.
A12: Alicate de corte flush + descarnador | B12: 18 | C12: SIM | D12: O descarnador é usado em todas as fases, mesmo sem soldar.
A13: Óculos de proteção (2 pares) | B13: 8 | C13: SIM | D13: ⚠️ O risco ocular real NÃO é o fumo — é o terminal cortado a saltar. Dois pares: um para cada um.
A14: Kit de prática (Whadda WSI102 ou similar) | B14: 15 | C14: SIM | D14: ⚠️ FAZER ~100 JUNTAS ANTES DE TOCAR NO PI DE 95 EUROS. 15 euros contra o risco de destruir 95: não há discussão. E é o sítio certo para a Lara experimentar — uma placa de treino não tem nada a perder.
A15: Multímetro (se não tiverem) | B15: 25 | C15: SIM | D15: Serve para identificar os componentes recebidos, medir os contactos do botão e do rocker, verificar a coluna e testar a alimentação do MAX98357A.
A16: Ventoinha USB pequena | B16: 12 | C16: RECOMENDADO | D16: Posta a PUXAR o ar para longe das caras. A seguir a 'não se debruçar sobre a junta', é o maior ganho de segurança por euro. Uma janela aberta e esta ventoinha valem mais que um extrator caro mal colocado.
A17: Extrator de fumos com filtro de carvão | B17: 30 | C17: OPCIONAL | D17: Só funciona a 10-15 cm da junta. A HSE avisa que estas unidades 'do not capture all of the fume particles'. Janela + ventoinha primeiro; isto se soldarem muito.
A18: Estação de ar quente / microscópio / pasta de solda | C18: NAO COMPRAR | D18: ⚠️ Nada disto é preciso para este projeto. São a tentação clássica de quem começa.
A20: TOTAL DA BANCADA (só os essenciais) | B20: =SUMIF(C5:C18,"SIM",B5:B18) -> 147
A22: SEGURANÇA — os factos, sem alarmismo
A23: O CHUMBO NÃO EVAPORA. Funde a 327C e ferve a 1749C; soldamos a 350C. A via de exposição real é MAO-BOCA, não o ar (Columbia University EHS: 'the primary route of exposure to lead from soldering is ingestion'). LAVAR AS MAOS COM SABAO a seguir resolve quase tudo. Mesmo assim, recomendo solda sem chumbo: apaga a questão inteira.
A25: O FUMO QUE SE VE E O FLUXO, NAO O METAL — e ESSE é o risco a sério. A HSE britânica classifica o fumo de colofónia como 'a common cause of occupational asthma', e a sensibilização é PERMANENTE: uma vez sensibilizado, doses mínimas desencadeiam crise.
A27: AS TRES MEDIDAS, POR ORDEM DE EFICACIA POR EURO:
A28: 1. NAO SE DEBRUCAR SOBRE A JUNTA. Custa zero e é o maior ganho isolado.
A29: 2. Janela aberta + ventoinha a PUXAR o ar para longe das caras (~12 euros).
A30: 3. Extrator com filtro de carvão, e só serve a 10-15 cm da junta (~30 euros).
A32: REGRAS DE CASA: ferro sempre no suporte · cabo longe da borda · cabelo apanhado e sem mangas largas · OCULOS DE PROTECAO (o risco é o terminal cortado a saltar, não o fumo) · nada de comer nem beber na bancada · lavar as mãos a seguir · limpar a bancada com pano HUMIDO, nunca varrer · nunca deixar o ferro ligado sem vigilância · queimadura: água fria corrente 20 minutos.
A34: QUANDO É QUE A LARA PODE SOLDAR? O manual de segurança da FIRST Robotics normaliza 10-13 anos com supervisão 1:1, e o FTC aceita a partir dos 12. O critério prático é melhor que a idade: ELA PODE SOLDAR QUANDO PUSER O FERRO NO SUPORTE DE FORMA FIAVEL ENTRE JUNTAS, sem ter de se lembrar. Testar isso no kit de prática, que não tem nada a perder.
A36: QUANTA SOLDADURA É PRECISA AGORA
A37: Com as escolhas certas na lista de compras, quase nenhuma:
A38: O ferro e os materiais já chegaram. Primeiro praticar numa placa descartável. Depois testar o MAX98357A, a coluna e os controlos na breadboard. Soldar o pente apenas depois de confirmar a orientação e a pinagem.
... A44: OPINIAO HONESTA: aprendam a soldar. São umas 4 horas de prática e elimina a causa número um de robôs de hobby que 'às vezes funcionam' — contactos intermitentes. Mas usem as soluções sem soldar no caminho de POTENCIA, porque é aí que uma junta má deixa de ser uma chatice e passa a ser um perigo.
